Workbook

Sheet VERSEMENT
A1: VERSEMENT ETS N'DI MBE
A2: Nom et Prenom | B2: Date | C2: montant
A3: ANDRE SOH | B3: 44867 | C3: 1000000
A4: PALO VALENTIN | B4: 44893 | C4: 1000000
A5: WAFFO MAURICE | B5: 44893 | C5: 1000000
A6: KENDOUM ERNEST | B6: 44895 | C6: 1000000
A7: TAMPOLLA SERGE | B7: 44904 | C7: 1000000
A8: FONGANG JEAN NOEL | B8: 44953 | C8: 2000000
A9: TALLA VALENTIN | B9: 45362 | C9: 1000000
A10: TOTAL VERSEMENT | B10: =SUM(C3:C9) -> 8000000

Sheet Dashboard
A1: TABLEAU DE BORD
A2: Date de mise à jour : | B2: =TODAY() -> 46140
A3: Résumé financier
A4: Capital total | B4: =Membres!C9 -> 8000000
A5: Prêts en cours | B5: =SUMIF(Prêts!K:K,"En cours",Prêts!C:C) -> 11500000
A6: Prét cumulé | B6: =Prêts!C2 -> 28860000
A7: Remboursements reçus | B7: =Prêts!I2 -> 30733500
A8: Intérêts générés | B8: =Prêts!H2 -> 4023499
A9: Solde disponible | B9: =B4+B8-B5 -> 523499

Sheet Membres
A1: Nom du Membre | B1: Date d'entrée | C1: Versement initial | D1: Gain Intérêt | E1: Capital cumulé
A2: ANDRE SOH | B2: 44867 | C2: 1000000 | D2: =C2*Prêts!H2/C9 -> 502937.38 | E2: =C2+D2 -> 1502937.4
A3: PALO VALENTIN | B3: 44893 | C3: 1000000 | D3: =C3*Prêts!H2/C9 -> 502937.38 | E3: =C3+D3 -> 1502937.4
A4: WAFFO MAURICE | B4: 44893 | C4: 1000000 | D4: =C4*Prêts!H2/C9 -> 502937.38 | E4: =C4+D4 -> 1502937.4
A5: KENDOUM ERNEST | B5: 44895 | C5: 1000000 | D5: =C5*Prêts!H2/C9 -> 502937.38 | E5: =C5+D5 -> 1502937.4
A6: TAMPOLLA SERGE | B6: 44904 | C6: 1000000 | D6: =C6*Prêts!H2/C9 -> 502937.38 | E6: =C6+D6 -> 1502937.4
A7: FONGANG JEAN NOEL | B7: 44953 | C7: 2000000 | D7: =C7*Prêts!H2/C9 -> 1005874.8 | E7: =C7+D7 -> 3005874.8
A8: TALLA VALENTIN | B8: 45362 | C8: 1000000 | D8: =C8*Prêts!H2/C9 -> 502937.38 | E8: =C8+D8 -> 1502937.4
C9: =SUM(C2:C8) -> 8000000 | D9: =SUM(D2:D8) -> 4023499 | E9: =C9+D9 -> 12023499

Sheet Prêts
A1: Situation des Prets | L1: Situation des Remboursements
C2: =SUM(C4:C19) -> 28860000 | H2: =SUM(H4:H40) -> 4023499 | I2: =SUM(I4:I19) -> 30733500 | J2: =SUM(J4:J34) -> 90082.717 | L2: 1 er Mois | O2: 2eme Mois | R2: 3eme Mois | X2: =SUM(X4:X19) -> 9860.0136
A3: ID Prêt | B3: ID Membre | C3: Montant | D3: Date du prêt | E3: Durée | F3: Taux | G3: échéance | H3: Interet | I3: Total Rmbs | J3: Encours | K3: Statut | L3: Attendu | M3: Rembourse | N3: Solde | O3: Attendu | P3: Rembourse | Q3: Solde | R3: Attendu | S3: Rembourse | T3: Solde | U3: Retart | W3: Rembourse | X3: Solde | Y3: En cours
A4: 1 | B4: KENDOUM ERNEST | C4: 1500000 | D4: 45358 | E4: =Paramètres!D1 -> 3 | F4: 0.02 | G4: =DATE(YEAR(D4),MONTH(D4)+E4,DAY(D4)) -> 45450 | H4: =M4+P4+S4+W4-C4 -> 290000 | I4: =M4+P4+S4+W4 -> 1790000 | J4: =X4 -> 572.01357 | K4: Terminé | L4: =C4*F4 +C4 -> 1530000 | N4: =L4-M4 -> 1530000 | O4: =N4*(1+F4) -> 1560600 | Q4: =O4-P4 -> 1560600 | R4: =Q4*(1+F4) -> 1591812 | T4: =R4-S4 -> 1591812 | U4: =3 -> 3 | V4: =T4*POWER((1+4%),U4) -> 1790572 | W4: =Remboursements!C15 -> 1790000 | X4: =V4-W4 -> 572.01357 | Y4: Terminé
A5: 2 | B5: TAMPOLLA SERGE | C5: 1000000 | D5: 45358 | E5: =Paramètres!D1 -> 3 | F5: 0.02 | G5: =DATE(YEAR(D5),MONTH(D5)+E5,DAY(D5)) -> 45450 | H5: =M5+P5+S5+W5-C5 -> 40000 | I5: =M5+P5+S5+W5 -> 1040000 | J5: =X5 -> 0 | K5: Terminé | L5: =C5*F5 +C5 -> 1020000 | M5: =Remboursements!C4 -> 20000 | N5: =L5-M5 -> 1000000 | O5: =N5*(1+F5) -> 1020000 | P5: =Remboursements!C5 -> 1020000 | Q5: =O5-P5 -> 0 | R5: =Q5*(1+F5) -> 0 | T5: =R5-S5 -> 0 | U5: 0 | V5: =T5*POWER((1+4%),U5) -> 0 | X5: =V5-W5 -> 0 | Y5: En retard
A6: 3 | B6: PALO VALENTIN | C6: 3000000 | D6: 45362 | E6: =Paramètres!D1 -> 3 | F6: 0.02 | G6: =DATE(YEAR(D6),MONTH(D6)+E6,DAY(D6)) -> 45454 | H6: =M6+P6+S6+W6-C6 -> 120000 | I6: =M6+P6+S6+W6 -> 3120000 | J6: =X6 -> 0 | K6: Terminé | L6: =C6*F6 +C6 -> 3060000 | M6: =Remboursements!C2 -> 60000 | N6: =L6-M6 -> 3000000 | O6: =N6*(1+F6) -> 3060000 | P6: =Remboursements!C6 -> 3060000 | Q6: =O6-P6 -> 0 | R6: =Q6*(1+F6) -> 0 | T6: =R6-S6 -> 0 | U6: 0 | V6: =T6*POWER((1+4%),U6) -> 0 | X6: =V6-W6 -> 0
A7: 4 | B7: FONGANG JEAN NOEL | C7: 2000000 | D7: 45367 | E7: =Paramètres!D1 -> 3 | F7: 0.02 | G7: =DATE(YEAR(D7),MONTH(D7)+E7,DAY(D7)) -> 45459 | H7: =M7+P7+S7+W7-C7 -> 80000 | I7: =M7+P7+S7+W7 -> 2080000 | J7: =X7 -> 0 | K7: Terminé | L7: =C7*F7 +C7 -> 2040000 | M7: =Remboursements!C3 -> 40000 | N7: =L7-M7 -> 2000000 | O7: =N7*(1+F7) -> 2040000 | P7: =Remboursements!C7 -> 2040000 | Q7: =O7-P7 -> 0 | R7: =Q7*(1+F7) -> 0 | T7: =R7-S7 -> 0 | U7: 0 | V7: =T7*POWER((1+4%),U7) -> 0 | X7: =V7-W7 -> 0
A8: 5 | B8: WAFFO MAURICE | C8: 2000000 | D8: 45462 | E8: 3 | F8: 0.02 | G8: =DATE(YEAR(D8),MONTH(D8)+E8,DAY(D8)) -> 45554 | H8: =M8+P8+S8+W8-C8 -> 120000 | I8: =M8+P8+S8+W8 -> 2120000 | J8: =X8 -> 2416 | K8: Terminé | L8: =C8*F8 +C8 -> 2040000 | N8: =L8-M8 -> 2040000 | O8: =N8*(1+F8) -> 2080800 | Q8: =O8-P8 -> 2080800 | R8: =Q8*(1+F8) -> 2122416 | S8: =Remboursements!C13 -> 2120000 | T8: =R8-S8 -> 2416 | U8: 0 | V8: =T8*POWER((1+4%),U8) -> 2416 | X8: =V8-W8 -> 2416
A9: 6 | B9: PALO VALENTIN | C9: 1500000 | D9: 45462 | E9: 3 | F9: 0.02 | G9: =DATE(YEAR(D9),MONTH(D9)+3,DAY(D9)) -> 45554 | H9: =M9+P9+S9+W9-C9 -> 90000 | I9: =M9+P9+S9+W9 -> 1590000 | J9: =X9 -> 0 | K9: Terminé | L9: =C9*F9 +C9 -> 1530000 | M9: =Remboursements!C8 -> 30000 | N9: =L9-M9 -> 1500000 | O9: =N9*(1+F9) -> 1530000 | P9: =Remboursements!C10 -> 30000 | Q9: =O9-P9 -> 1500000 | R9: =Q9*(1+F9) -> 1530000 | S9: =Remboursements!C11 -> 1530000 | T9: =R9-S9 -> 0 | U9: 0 | V9: =T9*POWER((1+4%),U9) -> 0 | X9: =V9-W9 -> 0
A10: 7 | B10: FONGANG JEAN NOEL | C10: 1360000 | D10: 45462 | E10: 3 | F10: 0.02 | G10: =DATE(YEAR(D10),MONTH(D10)+3,DAY(D10)) -> 45554 | H10: =M10+P10+S10+W10-C10 -> 83500 | I10: =M10+P10+S10+W10 -> 1443500 | J10: =X10 -> 0 | K10: Terminé | L10: =C10*F10 +C10 -> 1387200 | N10: =L10-M10 -> 1387200 | O10: =N10*(1+F10) -> 1414944 | Q10: =O10-P10 -> 1414944 | R10: =Q10*(1+F10) -> 1443242.9 | S10: =Remboursements!C12 -> 1443500 | T10: 0 | U10: 0 | V10: =T10*POWER((1+4%),U10) -> 0 | X10: =V10-W10 -> 0
A11: 8 | B11: TALLA VALENTIN | C11: 2000000 | D11: 45462 | E11: 3 | F11: 0.02 | G11: =DATE(YEAR(D11),MONTH(D11)+3,DAY(D11)) -> 45554 | H11: =M11+P11+S11+W11-C11 -> 180000 | I11: =M11+P11+S11+W11 -> 2180000 | J11: =X11 -> 832 | K11: Terminé | L11: =C11*F11 +C11 -> 2040000 | M11: =Remboursements!C9 -> 40000 | N11: =L11-M11 -> 2000000 | O11: =N11*(1+F11) -> 2040000 | Q11: =O11-P11 -> 2040000 | R11: =Q11*(1+F11) -> 2080800 | S11: =Remboursements!C14 -> 580000 | T11: =R11-S11 -> 1500800 | U11: 1 | V11: =T11*POWER((1+4%),U11) -> 1560832 | W11: =Remboursements!C18 -> 1560000 | X11: =V11-W11 -> 832
A12: 9 | B12: FONGANG JEAN NOEL | C12: 2000000 | D12: 45555 | E12: 3 | F12: 0.02 | G12: =DATE(YEAR(D12),MONTH(D12)+3,DAY(D12)) -> 45646 | H12: =M12+P12+S12+W12-C12 -> 120000 | I12: =M12+P12+S12+W12 -> 2120000 | J12: =X12 -> 0 | K12: Terminé | L12: =C12*F12 +C12 -> 2040000 | M12: =Remboursements!C17 -> 40000 | N12: =L12-M12 -> 2000000 | O12: =N12*(1+F12) -> 2040000 | P12: =Remboursements!C20 -> 40000 | Q12: =O12-P12 -> 2000000 | R12: =Q12*(1+F12) -> 2040000 | S12: =Remboursements!C21 -> 2040000 | T12: =R12-S12 -> 0 | U12: 0 | V12: =T12*POWER((1+4%),U12) -> 0 | X12: =V12-W12 -> 0
A13: 10 | B13: WAFFO MAURICE | C13: 2000000 | D13: 45555 | E13: 3 | F13: 0.02 | G13: =DATE(YEAR(D13),MONTH(D13)+3,DAY(D13)) -> 45646 | H13: =M13+P13+S13+W13-C13 -> 120000 | I13: =M13+P13+S13+W13 -> 2120000 | J13: =X13 -> 2416 | K13: Terminé | L13: =C13*F13 +C13 -> 2040000 | N13: =L13-M13 -> 2040000 | O13: =N13*(1+F13) -> 2080800 | Q13: =O13-P13 -> 2080800 | R13: =Q13*(1+F13) -> 2122416 | S13: =Remboursements!C22 -> 2120000 | T13: =R13-S13 -> 2416 | U13: 0 | V13: =T13*POWER((1+4%),U13) -> 2416 | X13: =V13-W13 -> 2416
A14: 11 | B14: PALO VALENTIN | C14: 1500000 | D14: 45555 | E14: 3 | F14: 0.02 | G14: =DATE(YEAR(D14),MONTH(D14)+3,DAY(D14)) -> 45646 | H14: =M14+P14+S14+W14-C14 -> 90000 | I14: =M14+P14+S14+W14 -> 1590000 | J14: =X14 -> 0 | K14: Terminé | L14: =C14*F14 +C14 -> 1530000 | M14: =Remboursements!C16 -> 30000 | N14: =L14-M14 -> 1500000 | O14: =N14*(1+F14) -> 1530000 | P14: =Remboursements!C19 -> 30000 | Q14: =O14-P14 -> 1500000 | R14: =Q14*(1+F14) -> 1530000 | S14: =Remboursements!C23 -> 1530000 | T14: =R14-S14 -> 0 | U14: 0 | V14: =T14*POWER((1+4%),U14) -> 0 | X14: =V14-W14 -> 0
A15: 12 | B15: KENDOUM ERNEST | C15: 1000000 | D15: 45581 | E15: 3 | F15: 0.02 | G15: =DATE(YEAR(D15),MONTH(D15)+3,DAY(D15)) -> 45673 | H15: =M15+P15+S15+W15-C15 -> 60000 | I15: =M15+P15+S15+W15 -> 1060000 | J15: =X15 -> 1208 | K15: Terminé | L15: =C15*F15 +C15 -> 1020000 | N15: =L15-M15 -> 1020000 | O15: =N15*(1+F15) -> 1040400 | Q15: =O15-P15 -> 1040400 | R15: =Q15*(1+F15) -> 1061208 | S15: =Remboursements!C24 -> 1060000 | T15: =R15-S15 -> 1208 | U15: 0 | V15: =T15*POWER((1+4%),U15) -> 1208 | X15: =V15-W15 -> 1208
A16: 13 | B16: TALLA VALENTIN | C16: 2000000 | D16: 45600 | E16: 3 | F16: 0.02 | G16: =DATE(YEAR(D16),MONTH(D16)+3,DAY(D16)) -> 45692 | H16: =M16+P16+S16+W16-C16 -> 120000 | I16: =M16+P16+S16+W16 -> 2120000 | J16: =X16 -> 2416 | K16: Terminé | L16: =C16*F16 +C16 -> 2040000 | N16: =L16-M16 -> 2040000 | O16: =N16*(1+F16) -> 2080800 | Q16: =O16-P16 -> 2080800 | R16: =Q16*(1+F16) -> 2122416 | S16: =Remboursements!C27 -> 2120000 | T16: =R16-S16 -> 2416 | U16: 0 | V16: =T16*POWER((1+4%),U16) -> 2416 | X16: =V16-W16 -> 2416
A17: 14 | B17: PALO VALENTIN | C17: 2000000 | D17: 45653 | E17: 3 | F17: 0.02 | G17: =DATE(YEAR(D17),MONTH(D17)+3,DAY(D17)) -> 45743 | H17: =M17+P17+S17+W17-C17 -> 120000 | I17: =M17+P17+S17+W17 -> 2120000 | J17: =X17 -> 0 | K17: Terminé | L17: =C17*F17 +C17 -> 2040000 | M17: =Remboursements!C25 -> 40000 | N17: =L17-M17 -> 2000000 | O17: =N17*(1+F17) -> 2040000 | P17: 40000 | Q17: =O17-P17 -> 2000000 | R17: =Q17*(1+F17) -> 2040000 | S17: 2040000 | T17: =R17-S17 -> 0 | U17: 0 | V17: =T17*POWER((1+4%),U17) -> 0 | X17: =V17-W17 -> 0
A18: 15 | B18: FONGANG JEAN NOEL | C18: 2000000 | D18: 45653 | E18: 3 | F18: 0.02 | G18: =DATE(YEAR(D18),MONTH(D18)+3,DAY(D18)) -> 45743 | H18: =M18+P18+S18+W18-C18 -> 120000 | I18: =M18+P18+S18+W18 -> 2120000 | J18: =X18 -> 0 | K18: Terminé | L18: =C18*F18 +C18 -> 2040000 | M18: =Remboursements!C26 -> 40000 | N18: =L18-M18 -> 2000000 | O18: =N18*(1+F18) -> 2040000 | P18: 40000 | Q18: =O18-P18 -> 2000000 | R18: =Q18*(1+F18) -> 2040000 | S18: 2040000 | T18: =R18-S18 -> 0 | U18: 0 | V18: =T18*POWER((1+4%),U18) -> 0 | X18: =V18-W18 -> 0
A19: 16 | B19: WAFFO MAURICE | C19: 2000000 | D19: 45654 | E19: 3 | F19: 0.02 | G19: =DATE(YEAR(D19),MONTH(D19)+3,DAY(D19)) -> 45744 | H19: =M19+P19+S19+W19-C19 -> 120000 | I19: =M19+P19+S19+W19 -> 2120000 | J19: =X19 -> 0 | K19: Terminé | L19: =C19*F19 +C19 -> 2040000 | N19: =L19-M19 -> 2040000 | O19: =N19*(1+F19) -> 2080800 | P19: 2120000 | R19: =Q19*(1+F19) -> 0 | T19: =R19-S19 -> 0 | U19: 0 | V19: =T19*POWER((1+4%),U19) -> 0 | X19: =V19-W19 -> 0
A20: 17 | B20: TAMPOLLA SERGE | C20: 1000000 | D20: 45706 | E20: 3 | F20: 0.02 | G20: =DATE(YEAR(D20),MONTH(D20)+3,DAY(D20)) -> 45795 | H20: 20000 | I20: =M20+P20+S20+W20 -> 1060000 | J20: =X20 -> 400 | K20: Terminé | L20: =C20*F20 +C20 -> 1020000 | M20: 20000 | N20: =L20-M20 -> 1000000 | O20: =N20*(1+F20) -> 1020000 | Q20: =O20-P20 -> 1020000 | R20: =Q20*(1+F20) -> 1040400 | S20: 1040000 | T20: =R20-S20 -> 400 | U20: 0 | V20: =T20*POWER((1+4%),U20) -> 400 | X20: =V20-W20 -> 400
A21: 18 | B21: TALLA VALENTIN | C21: 2000000 | D21: 45706 | E21: 3 | F21: 0.02 | G21: =DATE(YEAR(D21),MONTH(D21)+3,DAY(D21)) -> 45795 | H21: =M21+P21+S21+W21-C21 -> 120000 | I21: =M21+P21+S21+W21 -> 2120000 | J21: =X21 -> 2416 | K21: Terminé | L21: =C21*F21 +C21 -> 2040000 | N21: =L21-M21 -> 2040000 | O21: =N21*(1+F21) -> 2080800 | Q21: =O21-P21 -> 2080800 | R21: =Q21*(1+F21) -> 2122416 | S21: 2120000 | T21: =R21-S21 -> 2416 | U21: 0 | V21: =T21*POWER((1+4%),U21) -> 2416 | X21: =V21-W21 -> 2416
A22: 19 | B22: WAFFO MAURICE | C22: 2000000 | D22: 45708 | E22: 3 | F22: 0.02 | G22: =DATE(YEAR(D22),MONTH(D22)+3,DAY(D22)) -> 45797 | H22: =M22+P22+S22+W22-C22 -> 120000 | I22: =M22+P22+S22+W22 -> 2120000 | J22: =X22 -> 2416 | K22: Terminé | L22: =C22*F22 +C22 -> 2040000 | N22: =L22-M22 -> 2040000 | O22: =N22*(1+F22) -> 2080800 | Q22: =O22-P22 -> 2080800 | R22: =Q22*(1+F22) -> 2122416 | S22: 2120000 | T22: =R22-S22 -> 2416 | U22: 0 | V22: =T22*POWER((1+4%),U22) -> 2416 | X22: =V22-W22 -> 2416
A23: 20 | B23: FONGANG JEAN NOEL | C23: 2000000 | D23: 45748 | E23: 3 | F23: 0.02 | G23: =DATE(YEAR(D23),MONTH(D23)+3,DAY(D23)) -> 45839 | H23: =M23+P23+S23+W23-C23 -> 80000 | I23: =M23+P23+S23+W23 -> 2080000 | J23: =X23 -> 0 | K23: Terminé | L23: =C23*F23 +C23 -> 2040000 | M23: 40000 | N23: =L23-M23 -> 2000000 | O23: =N23*(1+F23) -> 2040000 | P23: 2040000 | Q23: =O23-P23 -> 0 | R23: =Q23*(1+F23) -> 0 | T23: =R23-S23 -> 0 | U23: 0 | V23: =T23*POWER((1+4%),U23) -> 0 | X23: =V23-W23 -> 0
A24: 21 | B24: PALO VALENTIN | C24: 2000000 | D24: 45751 | E24: 3 | F24: 0.02 | G24: =DATE(YEAR(D24),MONTH(D24)+3,DAY(D24)) -> 45842 | H24: =M24+P24+S24+W24-C24 -> 120000 | I24: =M24+P24+S24+W24 -> 2120000 | J24: =X24 -> 0 | K24: Terminé | L24: =C24*F24 +C24 -> 2040000 | M24: 40000 | N24: =L24-M24 -> 2000000 | O24: =N24*(1+F24) -> 2040000 | P24: 40000 | Q24: =O24-P24 -> 2000000 | R24: =Q24*(1+F24) -> 2040000 | S24: 2040000 | T24: =R24-S24 -> 0 | U24: 0 | V24: =T24*POWER((1+4%),U24) -> 0 | X24: =V24-W24 -> 0
A25: 22 | B25: TALLA VALENTIN | C25: 3000000 | D25: 45793 | E25: 3 | F25: 0.02 | G25: =DATE(YEAR(D25),MONTH(D25)+3,DAY(D25)) -> 45885 | H25: =M25+P25+S25+W25-C25 -> 180000 | I25: =M25+P25+S25+W25 -> 3180000 | J25: =X25 -> 3624 | K25: Terminé | L25: =C25*F25 +C25 -> 3060000 | N25: =L25-M25 -> 3060000 | O25: =N25*(1+F25) -> 3121200 | Q25: =O25-P25 -> 3121200 | R25: =Q25*(1+F25) -> 3183624 | S25: 3180000 | T25: =R25-S25 -> 3624 | U25: 0 | V25: =T25*POWER((1+4%),U25) -> 3624 | X25: =V25-W25 -> 3624
A26: 23 | B26: TAMPOLLA SERGE | C26: 1000000 | D26: 45798 | E26: 3 | F26: 0.02 | G26: =DATE(YEAR(D26),MONTH(D26)+3,DAY(D26)) -> 45890 | H26: =M26+P26+S26+W26-C26 -> 60000 | I26: =M26+P26+S26+W26 -> 1060000 | J26: =X26 -> 1208 | K26: Terminé | L26: =C26*F26 +C26 -> 1020000 | N26: =L26-M26 -> 1020000 | O26: =N26*(1+F26) -> 1040400 | Q26: =O26-P26 -> 1040400 | R26: =Q26*(1+F26) -> 1061208 | S26: 1060000 | T26: =R26-S26 -> 1208 | V26: =T26*POWER((1+4%),U27) -> 1208 | X26: =V26-W26 -> 1208
A27: 24 | B27: FONGANG JEAN NOEL | C27: 2000000 | D27: 45840 | E27: 3 | F27: 0.02 | G27: =DATE(YEAR(D27),MONTH(D27)+3,DAY(D27)) -> 45932 | H27: =M27+P27+S27+W27-C27 -> 120000 | I27: =M27+P27+S27+W27 -> 2120000 | J27: =X27 -> 2512.64 | K27: Terminé | L27: =C27*F27 +C27 -> 2040000 | N27: =L27-M27 -> 2040000 | O27: =N27*(1+F27) -> 2080800 | Q27: =O27-P27 -> 2080800 | R27: =Q27*(1+F27) -> 2122416 | S27: 2120000 | T27: =R27-S27 -> 2416 | U27: 0 | V27: =T27*POWER((1+4%),U28) -> 2512.64 | X27: =V27-W27 -> 2512.64
A28: 25 | B28: PALO VALENTIN | C28: 2000000 | D28: 45847 | E28: 3 | F28: 0.02 | G28: =DATE(YEAR(D28),MONTH(D28)+3,DAY(D28)) -> 45939 | H28: =M28+P28+S28+W28-C28 -> 200000 | I28: =M28+P28+S28+W28 -> 2200000 | J28: =X28 -> 0 | K28: Terminé | L28: =C28*F28 +C28 -> 2040000 | M28: 40000 | N28: =L28-M28 -> 2000000 | O28: =N28*(1+F28) -> 2040000 | P28: 40000 | Q28: =O28-P28 -> 2000000 | R28: =Q28*(1+F28) -> 2040000 | S28: 40000 | T28: =R28-S28 -> 2000000 | U28: 1 | V28: =T28*POWER((1+4%),U28) -> 2080000 | W28: 2080000 | X28: =V28-W28 -> 0
A29: 26 | B29: WAFFO MAURICE | C29: 2000001 | D29: 45798 | E29: 3 | F29: 0.02 | G29: =DATE(YEAR(D29),MONTH(D29)+3,DAY(D29)) -> 45890 | H29: =M29+P29+S29+W29-C29 -> 119999 | I29: =M29+P29+S29+W29 -> 2120000 | J29: =X29 -> 2513.7437 | K29: Terminé | L29: =C29*F29 +C29 -> 2040001 | N29: =L29-M29 -> 2040001 | O29: =N29*(1+F29) -> 2080801 | Q29: =O29-P29 -> 2080801 | R29: =Q29*(1+F29) -> 2122417.1 | S29: 2120000 | T29: =R29-S29 -> 2417.0612 | U29: 1 | V29: =T29*POWER((1+4%),U29) -> 2513.7437 | X29: =V29-W29 -> 2513.7437
A30: 27 | B30: TAMPOLLA SERGE | C30: 1000000 | D30: 45876 | E30: 3 | F30: 0.02 | G30: =DATE(YEAR(D30),MONTH(D30)+3,DAY(D30)) -> 45968 | H30: =M30+P30+S30+W30-C30 -> 100000 | I30: =M30+P30+S30+W30 -> 1100000 | J30: =X30 -> 3656.32 | K30: Terminé | L30: =C30*F30 +C30 -> 1020000 | N30: =L30-M30 -> 1020000 | O30: =N30*(1+F30) -> 1040400 | Q30: =O30-P30 -> 1040400 | R30: =Q30*(1+F30) -> 1061208 | T30: =R30-S30 -> 1061208 | U30: 1 | V30: =T30*POWER((1+4%),U30) -> 1103656.3 | W30: 1100000 | X30: =V30-W30 -> 3656.32
A31: 28 | B31: WAFFO MAURICE | C31: 2000000 | D31: 45894 | E31: 3 | F31: 0.02 | G31: =DATE(YEAR(D31),MONTH(D31)+3,DAY(D31)) -> 45986 | H31: =M31+P31+S31+W31-C31 -> 120000 | I31: =M31+P31+S31+W31 -> 2120000 | J31: =X31 -> 2416 | K31: Terminé | L31: =C31*F31 +C31 -> 2040000 | N31: =L31-M31 -> 2040000 | O31: =N31*(1+F31) -> 2080800 | Q31: =O31-P31 -> 2080800 | R31: =Q31*(1+F31) -> 2122416 | S31: 2120000 | T31: =R31-S31 -> 2416 | U31: 0 | V31: =T31*POWER((1+4%),U31) -> 2416 | X31: =V31-W31 -> 2416
A32: 29 | B32: TALLA VALENTIN | C32: 3000000 | D32: 45894 | E32: 3 | F32: 0.02 | G32: =DATE(YEAR(D32),MONTH(D32)+3,DAY(D32)) -> 45986 | H32: =M32+P32+S32+W32-C32 -> 180000 | I32: =M32+P32+S32+W32 -> 3180000 | J32: =X32 -> 3624 | K32: Terminé | L32: =C32*F32 +C32 -> 3060000 | N32: =L32-M32 -> 3060000 | O32: =N32*(1+F32) -> 3121200 | Q32: =O32-P32 -> 3121200 | R32: =Q32*(1+F32) -> 3183624 | S32: 3180000 | T32: =R32-S32 -> 3624 | U32: 0 | V32: =T32*POWER((1+4%),U32) -> 3624 | X32: =V32-W32 -> 3624
A33: 30 | B33: FONGANG JEAN NOEL | C33: 2000000 | D33: 46021 | E33: 3 | F33: 0.02 | G33: =DATE(YEAR(D33),MONTH(D33)+3,DAY(D33)) -> 46111 | H33: =M33+P33+S33+W33-C33 -> 120000 | I33: =M33+P33+S33+W33 -> 2120000 | J33: =X33 -> 2416 | K33: Terminé | L33: =C33*F33 +C33 -> 2040000 | N33: =L33-M33 -> 2040000 | O33: =N33*(1+F33) -> 2080800 | Q33: =O33-P33 -> 2080800 | R33: =Q33*(1+F33) -> 2122416 | S33: 2120000 | T33: =R33-S33 -> 2416 | U33: 0 | V33: =T33*POWER((1+4%),U33) -> 2416 | X33: =V33-W33 -> 2416
A34: 31 | B34: PALO VALENTIN | C34: 2500000 | D34: 45975 | E34: 3 | F34: 0.02 | G34: =DATE(YEAR(D34),MONTH(D34)+3,DAY(D34)) -> 46067 | H34: =M34+P34+S34+W34-C34 -> 100000 | I34: =M34+P34+S34+W34 -> 2600000 | J34: =X34 -> 53020 | K34: Terminé | L34: =C34*F34 +C34 -> 2550000 | N34: =L34-M34 -> 2550000 | O34: =N34*(1+F34) -> 2601000 | Q34: =O34-P34 -> 2601000 | R34: =Q34*(1+F34) -> 2653020 | S34: 2600000 | T34: =R34-S34 -> 53020 | U34: 0 | V34: =T34*POWER((1+4%),U34) -> 53020 | X34: =V34-W34 -> 53020
A35: 32 | B35: TAMPOLLA SERGE | C35: 1500000 | D35: 45988 | E35: 3 | F35: 0.02 | G35: =DATE(YEAR(D35),MONTH(D35)+3,DAY(D35)) -> 46080 | H35: =M35+P35+S35+W35-C35 -> 90000 | I35: =M35+P35+S35+W35 -> 1590000 | J35: =X35 -> 1812 | K35: Terminé | L35: =C35*F35 +C35 -> 1530000 | N35: =L35-M35 -> 1530000 | O35: =N35*(1+F35) -> 1560600 | Q35: =O35-P35 -> 1560600 | R35: =Q35*(1+F35) -> 1591812 | S35: 1590000 | T35: =R35-S35 -> 1812 | U35: 0 | V35: =T35*POWER((1+4%),U35) -> 1812 | X35: =V35-W35 -> 1812
A36: 33 | B36: WAFFO MAURICE | C36: 2000000 | D36: 45988 | E36: 3 | F36: 0.02 | G36: =DATE(YEAR(D36),MONTH(D36)+3,DAY(D36)) -> 46080 | H36: =M36+P36+S36+W36-C36 -> 120000 | I36: =M36+P36+S36+W36 -> 2120000 | J36: =X36 -> 2416 | K36: Terminé | L36: =C36*F36 +C36 -> 2040000 | N36: =L36-M36 -> 2040000 | O36: =N36*(1+F36) -> 2080800 | Q36: =O36-P36 -> 2080800 | R36: =Q36*(1+F36) -> 2122416 | S36: 2120000 | T36: =R36-S36 -> 2416 | U36: 0 | V36: =T36*POWER((1+4%),U36) -> 2416 | X36: =V36-W36 -> 2416
A37: 34 | B37: TALLA VALENTIN | C37: 3000000 | D37: 45992 | E37: 3 | F37: 0.02 | G37: =DATE(YEAR(D37),MONTH(D37)+3,DAY(D37)) -> 46082 | H37: =M37+P37+S37+W37-C37 -> 180000 | I37: =M37+P37+S37+W37 -> 3180000 | J37: =X37 -> 3624 | K37: Terminé | L37: =C37*F37 +C37 -> 3060000 | N37: =L37-M37 -> 3060000 | O37: =N37*(1+F37) -> 3121200 | Q37: =O37-P37 -> 3121200 | R37: =Q37*(1+F37) -> 3183624 | S37: 3180000 | T37: =R37-S37 -> 3624 | U37: 0 | V37: =T37*POWER((1+4%),U37) -> 3624 | X37: =V37-W37 -> 3624
A38: 35 | B38: PALO VALENTIN | C38: 2500000 | D38: 46071 | E38: 3 | F38: 0.02 | G38: =DATE(YEAR(D38),MONTH(D38)+3,DAY(D38)) -> 46160 | I38: =M38+P38+S38+W38 -> 0 | J38: =X38 -> 2759140.8 | K38: En cours | L38: =C38*F38 +C38 -> 2550000 | N38: =L38-M38 -> 2550000 | O38: =N38*(1+F38) -> 2601000 | Q38: =O38-P38 -> 2601000 | R38: =Q38*(1+F38) -> 2653020 | T38: =R38-S38 -> 2653020 | U38: 1 | V38: =T38*POWER((1+4%),U38) -> 2759140.8 | X38: =V38-W38 -> 2759140.8
A39: 36 | B39: TAMPOLLA SERGE | C39: 2000000 | D39: 46078 | E39: 3 | F39: 0.02 | G39: =DATE(YEAR(D39),MONTH(D39)+3,DAY(D39)) -> 46167 | I39: =M39+P39+S39+W39 -> 0 | J39: =X39 -> 2295605.1 | K39: En cours | L39: =C39*F39 +C39 -> 2040000 | N39: =L39-M39 -> 2040000 | O39: =N39*(1+F39) -> 2080800 | Q39: =O39-P39 -> 2080800 | R39: =Q39*(1+F39) -> 2122416 | T39: =R39-S39 -> 2122416 | U39: 2 | V39: =T39*POWER((1+4%),U39) -> 2295605.1 | X39: =V39-W39 -> 2295605.1
A40: 37 | B40: WAFFO MAURICE | C40: 2000000 | D40: 46081 | E40: 3 | F40: 0.02 | G40: =DATE(YEAR(D40),MONTH(D40)+3,DAY(D40)) -> 46170 | I40: =M40+P40+S40+W40 -> 0 | J40: =X40 -> 2387429.4 | K40: En cours | L40: =C40*F40 +C40 -> 2040000 | N40: =L40-M40 -> 2040000 | O40: =N40*(1+F40) -> 2080800 | Q40: =O40-P40 -> 2080800 | R40: =Q40*(1+F40) -> 2122416 | T40: =R40-S40 -> 2122416 | U40: 3 | V40: =T40*POWER((1+4%),U40) -> 2387429.4 | X40: =V40-W40 -> 2387429.4
...

Sheet Remboursements
A1: ID | B1: Membre | C1: Montant remboursé | D1: Date du remboursement
A2: 1 | B2: PALO VALENTIN | C2: 60000 | D2: 45394
A3: 2 | B3: FONGANG JEAN NOEL | C3: 40000 | D3: 45402
A4: 3 | B4: TAMPOLLA SERGE | C4: 20000 | D4: 45428
A5: 4 | B5: TAMPOLLA SERGE | C5: 1020000 | D5: 45448
A6: 5 | B6: PALO VALENTIN | C6: 3060000 | D6: 45454
A7: 6 | B7: FONGANG JEAN NOEL | C7: 2040000 | D7: 45457
A8: 7 | B8: PALO VALENTIN | C8: 30000 | D8: 45492
A9: 8 | B9: TALLA VALENTIN | C9: 40000 | D9: 45476
A10: 9 | B10: PALO VALENTIN | C10: 30000 | D10: 45492
A11: 10 | B11: PALO VALENTIN | C11: 1530000 | D11: 45554
A12: 11 | B12: FONGANG JEAN NOEL | C12: 1443500 | D12: 45549
A13: 12 | B13: WAFFO MAURICE | C13: 2120000 | D13: 45553
... A56: 55 | B56: FONGANG JEAN NOEL | C56: 2120000 | D56: 46113
A57: 56
A58: 57
A59: 58
A60: 59
A61: 60

Sheet Paramètres
A1: 0.02 | B1: 0.04 | C1: 0.02 | D1: 3

Sheet Cotisations
A1: Date | B1: ANDRE SOH | C1: PALO VALENTIN | D1: WAFFO MAURICE | E1: KENDOUM ERNEST | F1: TAMPOLLA SERGE | G1: FONGANG JEAN NOEL | H1: TALLA VALENTIN
A2: Cotisation | B2: =SUM(B3:B38) -> 1000000 | C2: =SUM(C3:C38) -> 1000000 | D2: =SUM(D3:D38) -> 1000000 | E2: =SUM(E3:E38) -> 1000000 | F2: =SUM(F3:F38) -> 1000000 | G2: =SUM(G3:G38) -> 2000000 | H2: =SUM(H3:H38) -> 1000000
A3: 44867 | B3: 1000000
A4: 44893 | C4: 1000000 | D4: 1000000
A5: 44895 | E5: 1000000
A6: 44904 | F6: 1000000
A7: 44953 | G7: 2000000
A8: 45362 | H8: 1000000
